<?xml version="1.0" ?>
<!-- =================================================================================== -->
<!-- |    This document was autogenerated by xacro from src/robotino_hal/description/robotino.urdf.xacro | -->
<!-- |    EDITING THIS FILE BY HAND IS NOT RECOMMENDED                                 | -->
<!-- =================================================================================== -->
<robot name="robotino">
  <!-- Vertical offset of the wheels -->
  <!-- Base Link -->
  <link name="base_link">
    <visual>
      <geometry>
        <cylinder length="0.05" radius="0.225"/>
      </geometry>
      <material name="blue">
        <color rgba="0 0 1 1"/>
      </material>
    </visual>
    <collision>
      <geometry>
        <cylinder length="0.05" radius="0.225"/>
      </geometry>
    </collision>
    <inertial>
      <origin rpy="1.5707963267948966 0 0" xyz="0 0 0"/>
      <mass value="10"/>
      <inertia ixx="0.12864583333333335" ixy="0" ixz="0" iyy="0.12864583333333335" iyz="0" izz="0.25312500000000004"/>
    </inertial>
  </link>
  <!-- Base Footprint (Virtual Link) -->
  <link name="base_footprint"/>
  <joint name="base_joint" type="fixed">
    <parent link="base_footprint"/>
    <child link="base_link"/>
    <origin rpy="0 0 0" xyz="0 0 0.025"/>
  </joint>
  <link name="wheel_1_wheel">
    <visual>
      <geometry>
        <cylinder length="0.03" radius="0.085"/>
      </geometry>
      <material name="black">
        <color rgba="0 0 0 1"/>
      </material>
    </visual>
    <collision>
      <geometry>
        <cylinder length="0.03" radius="0.085"/>
      </geometry>
    </collision>
    <inertial>
      <origin rpy="1.5707963267948966 0 0" xyz="0 0 0"/>
      <mass value="0.5"/>
      <inertia ixx="0.0009406250000000002" ixy="0" ixz="0" iyy="0.0009406250000000002" iyz="0" izz="0.0018062500000000003"/>
    </inertial>
  </link>
  <joint name="wheel_1_joint" type="continuous">
    <parent link="base_link"/>
    <child link="wheel_1_wheel"/>
    <origin rpy="0 0 0" xyz="0.18 0.0 -0.05"/>
    <axis xyz="1 0 0"/>
  </joint>
  <link name="wheel_2_wheel">
    <visual>
      <geometry>
        <cylinder length="0.03" radius="0.085"/>
      </geometry>
      <material name="black">
        <color rgba="0 0 0 1"/>
      </material>
    </visual>
    <collision>
      <geometry>
        <cylinder length="0.03" radius="0.085"/>
      </geometry>
    </collision>
    <inertial>
      <origin rpy="1.5707963267948966 0 0" xyz="0 0 0"/>
      <mass value="0.5"/>
      <inertia ixx="0.0009406250000000002" ixy="0" ixz="0" iyy="0.0009406250000000002" iyz="0" izz="0.0018062500000000003"/>
    </inertial>
  </link>
  <joint name="wheel_2_joint" type="continuous">
    <parent link="base_link"/>
    <child link="wheel_2_wheel"/>
    <origin rpy="0 0 0" xyz="-0.08999999999999996 0.15588457268119896 -0.05"/>
    <axis xyz="1 0 0"/>
  </joint>
  <link name="wheel_3_wheel">
    <visual>
      <geometry>
        <cylinder length="0.03" radius="0.085"/>
      </geometry>
      <material name="black">
        <color rgba="0 0 0 1"/>
      </material>
    </visual>
    <collision>
      <geometry>
        <cylinder length="0.03" radius="0.085"/>
      </geometry>
    </collision>
    <inertial>
      <origin rpy="1.5707963267948966 0 0" xyz="0 0 0"/>
      <mass value="0.5"/>
      <inertia ixx="0.0009406250000000002" ixy="0" ixz="0" iyy="0.0009406250000000002" iyz="0" izz="0.0018062500000000003"/>
    </inertial>
  </link>
  <joint name="wheel_3_joint" type="continuous">
    <parent link="base_link"/>
    <child link="wheel_3_wheel"/>
    <origin rpy="0 0 0" xyz="-0.09000000000000008 -0.1558845726811989 -0.05"/>
    <axis xyz="1 0 0"/>
  </joint>
  <link name="laser_frame">
    <visual>
      <geometry>
        <box size="0.1 0.1 0.05"/>
      </geometry>
      <material name="red">
        <color rgba="1 0 0 1"/>
      </material>
    </visual>
    <collision>
      <geometry>
        <box size="0.1 0.1 0.05"/>
      </geometry>
    </collision>
    <inertial>
      <origin rpy="1.5707963267948966 0 0" xyz="0 0 0"/>
      <mass value="0.1"/>
      <inertia ixx="8.333333333333334e-05" ixy="0" ixz="0" iyy="8.333333333333334e-05" iyz="0" izz="0.00012500000000000003"/>
    </inertial>
  </link>
  <joint name="lidar_joint" type="fixed">
    <parent link="base_link"/>
    <child link="laser_frame"/>
    <origin rpy="0 0 0" xyz="0 0 0.05"/>
  </joint>
</robot>
